Workbook

Sheet Steelhead
A1: Date | B1: 1946 | C1: 1947 | D1: 1948 | E1: 1949 | F1: 1950 | G1: 1951 | H1: 1952 | I1: 1953 | J1: 1954 | K1: 1955 | L1: 1956 | M1: 1957 | N1: 1958 | O1: 1959 | P1: 1960 | Q1: 1961 | R1: 1962 | S1: 1963 | T1: 1964 | U1: 1965 | V1: 1966 | W1: 1967 | X1: 1968 | Y1: 1969 | Z1: 1970 | AA1: 1971 | AB1: 1972 | AC1: 1973 | AD1: 1974 | AE1: 1975 | AF1: 1976 | AG1: 1977 | AH1: 1978 | AI1: 1979 | AJ1: 1980 | AK1: 1981 | AL1: 1982 | AM1: 1983 | AN1: 1984 | AO1: 1985 | AP1: 1986 | AQ1: 1987 | AR1: 1988 | AS1: 1989 | AT1: 1990 | AU1: 1991 | AV1: 1992 | AW1: 1993 | AX1: 1994 | AY1: 1995 | AZ1: 1996 | BA1: 1997 | BB1: 1998 | BC1: 1999 | BD1: 2000 | BE1: 2001 | BF1: 2002 | BG1: 2003 | BH1: 2004 | BI1: 2005 | BJ1: 2006 | BK1: 2007 | BL1: 2008 | BM1: 2009 | BN1: 2010 | BO1: 2011 | BP1: 2012 | BQ1: 2013 | BR1: 2014 | BS1: 2015 | BT1: 2016 | BU1: 2017 | BV1: 2018 | BW1: 2019 | BX1: 2020 | BY1: 2021 | BZ1: 2022 | CA1: 2023 | CB1: 2024 | CC1: 2025
A2: 45467
A3: 45468 | BB3: 0
A4: 45469 | BB4: 0
A5: 45470 | BB5: 0
A6: 45471 | BB6: 0
A7: 45472 | BB7: 0
A8: 45473 | BB8: 0
A9: 45474 | BB9: 0
A10: 45475 | BB10: 0
A11: 45476 | BB11: 0
A12: 45477 | BB12: 0
A13: 45478 | BB13: 0 | BH13: 0
A14: 45479 | BB14: 0 | BH14: 0 | BU14: 0
A15: 45480 | AU15: 0 | AW15: 0 | BB15: 0 | BH15: 0 | BJ15: 0 | BU15: 0
A16: 45481 | AU16: 0 | AW16: 0 | BB16: 0 | BH16: 0 | BJ16: 0 | BU16: 0
A17: 45482 | AU17: 0 | AW17: 0 | BB17: 0 | BH17: 0 | BJ17: 0 | BU17: 0 | CB17: 0
A18: 45483 | AU18: 0 | AW18: 0 | BB18: 0 | BH18: 0 | BJ18: 0 | BU18: 0 | CB18: 0
A19: 45484 | AU19: 0 | AW19: 0 | BB19: 0 | BH19: 0 | BJ19: 0 | BS19: 0 | BU19: 0 | CB19: 0
A20: 45485 | AU20: 0 | AW20: 0 | BB20: 0 | BH20: 0 | BI20: 0 | BJ20: 0 | BS20: 0 | BU20: 0 | CB20: 0
A21: 45486 | AU21: 0 | AW21: 0 | BB21: 0 | BH21: 0 | BI21: 0 | BJ21: 0 | BS21: 0 | BU21: 0 | BW21: 0 | CB21: 0
A22: 45487 | AU22: 0 | AW22: 0 | AX22: 0 | BB22: 0 | BH22: 0 | BI22: 0 | BJ22: 0 | BS22: 0 | BT22: 0 | BU22: 0 | BW22: 0 | BY22: 0 | CB22: 0
A23: 45488 | AU23: 0 | AW23: 0 | AX23: 0 | BB23: 0 | BH23: 0 | BI23: 0 | BJ23: 0 | BR23: 0 | BS23: 0 | BT23: 0 | BU23: 0 | BW23: 0 | BY23: 0 | BZ23: 0 | CB23: 0
A24: 45489 | AU24: 0 | AW24: 0 | AX24: 0 | BB24: 0 | BG24: 0 | BH24: 0 | BI24: 0 | BJ24: 0 | BM24: 0 | BR24: 0 | BS24: 0 | BT24: 0 | BU24: 0 | BW24: 0 | BX24: 0 | BY24: 0 | BZ24: 0 | CB24: 0
A25: 45490 | AU25: 0 | AW25: 0 | AX25: 0 | BB25: 0 | BG25: 0 | BH25: 0 | BI25: 0 | BJ25: 1 | BM25: 0 | BR25: 0 | BS25: 0 | BT25: 0 | BU25: 0 | BV25: 0 | BW25: 0 | BX25: 0 | BY25: 0 | BZ25: 0 | CB25: 0
A26: 45491 | AU26: 0 | AW26: 0 | AX26: 0 | BB26: 0 | BG26: 0 | BH26: 0 | BI26: 0 | BJ26: 0 | BL26: 0 | BM26: 0 | BR26: 0 | BS26: 0 | BT26: 0 | BU26: 0 | BV26: 0 | BW26: 0 | BX26: 0 | BY26: 0 | BZ26: 0 | CB26: 0
A27: 45492 | AU27: 0 | AW27: 0 | AX27: 0 | BB27: 0 | BG27: 0 | BH27: 0 | BI27: 0 | BJ27: 0 | BL27: 0 | BM27: 0 | BR27: 0 | BS27: 0 | BT27: 0 | BU27: 0 | BV27: 0 | BW27: 0 | BX27: 0 | BY27: 0 | BZ27: 0 | CB27: 0
A28: 45493 | AU28: 0 | AW28: 0 | AX28: 0 | BB28: 0 | BC28: 0 | BG28: 0 | BH28: 0 | BI28: 0 | BJ28: 0 | BL28: 0 | BM28: 0 | BR28: 0 | BS28: 0 | BT28: 0 | BU28: 0 | BV28: 0 | BW28: 0 | BX28: 0 | BY28: 0 | BZ28: 0 | CA28: 0 | CB28: 0
A29: 45494 | AT29: 0 | AU29: 0 | AW29: 0 | AX29: 0 | BB29: 0 | BC29: 0 | BG29: 0 | BH29: 0 | BI29: 0 | BJ29: 0 | BL29: 0 | BM29: 0 | BR29: 0 | BS29: 0 | BT29: 0 | BU29: 0 | BV29: 0 | BW29: 0 | BX29: 0 | BY29: 0 | BZ29: 0 | CA29: 0 | CB29: 0
A30: 45495 | AT30: 0 | AU30: 0 | AW30: 0 | AX30: 0 | BB30: 0 | BC30: 0 | BG30: 0 | BH30: 0 | BI30: 0 | BJ30: 0 | BL30: 0 | BM30: 0 | BR30: 0 | BS30: 0 | BT30: 0 | BU30: 0 | BV30: 0 | BW30: 0 | BX30: 0 | BY30: 0 | BZ30: 0 | CA30: 0 | CB30: 0
A31: 45496 | AT31: 0 | AU31: 0 | AW31: 0 | AX31: 0 | BB31: 0 | BC31: 0 | BG31: 0 | BH31: 0 | BI31: 0 | BJ31: 0 | BL31: 0 | BM31: 0 | BP31: 0 | BQ31: 0 | BR31: 0 | BS31: 0 | BT31: 0 | BU31: 0 | BV31: 0 | BW31: 0 | BX31: 0 | BY31: 0 | BZ31: 0 | CA31: 0 | CB31: 0
A32: 45497 | AT32: 0 | AU32: 0 | AW32: 0 | AX32: 0 | BB32: 0 | BC32: 0 | BG32: 0 | BH32: 0 | BI32: 0 | BJ32: 0 | BL32: 0 | BM32: 0 | BP32: 0 | BQ32: 0 | BR32: 0 | BS32: 0 | BT32: 0 | BU32: 0 | BV32: 0 | BW32: 0 | BX32: 0 | BY32: 0 | BZ32: 0 | CA32: 0 | CB32: 0
A33: 45498 | AT33: 0 | AU33: 0 | AW33: 0 | AX33: 0 | BB33: 0 | BC33: 0 | BG33: 0 | BH33: 0 | BI33: 0 | BJ33: 0 | BL33: 0 | BM33: 0 | BP33: 0 | BQ33: 0 | BR33: 0 | BS33: 0 | BT33: 0 | BU33: 0 | BV33: 0 | BW33: 0 | BX33: 0 | BY33: 0 | BZ33: 0 | CA33: 0 | CB33: 0
A34: 45499 | AT34: 0 | AU34: 0 | AW34: 0 | AX34: 0 | BB34: 0 | BC34: 0 | BG34: 0 | BH34: 0 | BI34: 0 | BJ34: 0 | BL34: 0 | BM34: 0 | BP34: 0 | BQ34: 0 | BR34: 0 | BS34: 0 | BT34: 0 | BU34: 0 | BV34: 0 | BW34: 0 | BX34: 0 | BY34: 0 | BZ34: 0 | CA34: 0 | CB34: 0
A35: 45500 | AT35: 0 | AU35: 0 | AW35: 0 | AX35: 0 | BB35: 0 | BC35: 0 | BG35: 0 | BH35: 0 | BI35: 0 | BJ35: 0 | BL35: 0 | BM35: 0 | BP35: 0 | BQ35: 0 | BR35: 0 | BS35: 0 | BT35: 0 | BU35: 0 | BV35: 0 | BW35: 0 | BX35: 0 | BY35: 0 | BZ35: 0 | CA35: 1 | CB35: 0
A36: 45501 | AT36: 0 | AU36: 0 | AW36: 0 | AX36: 0 | AZ36: 0 | BB36: 0 | BC36: 0 | BG36: 0 | BH36: 0 | BI36: 0 | BJ36: 0 | BL36: 0 | BM36: 0 | BP36: 0 | BQ36: 0 | BR36: 0 | BS36: 0 | BT36: 0 | BU36: 0 | BV36: 0 | BW36: 0 | BX36: 0 | BY36: 0 | BZ36: 0 | CA36: 0 | CB36: 0
A37: 45502 | AT37: 0 | AU37: 0 | AW37: 0 | AX37: 0 | AZ37: 0 | BA37: 0 | BB37: 0 | BC37: 0 | BG37: 0 | BH37: 0 | BI37: 0 | BJ37: 0 | BL37: 0 | BM37: 0 | BP37: 0 | BQ37: 0 | BR37: 0 | BS37: 0 | BT37: 0 | BU37: 0 | BV37: 0 | BW37: 0 | BX37: 0 | BY37: 0 | BZ37: 0 | CA37: 0 | CB37: 0
A38: 45503 | AT38: 0 | AU38: 0 | AW38: 0 | AX38: 0 | AZ38: 0 | BA38: 0 | BB38: 0 | BC38: 0 | BG38: 0 | BH38: 0 | BI38: 0 | BJ38: 0 | BL38: 0 | BM38: 0 | BP38: 0 | BQ38: 0 | BR38: 0 | BS38: 0 | BT38: 0 | BU38: 0 | BV38: 0 | BW38: 0 | BX38: 0 | BY38: 0 | BZ38: 0 | CA38: 0 | CB38: 0
A39: 45504 | AT39: 0 | AU39: 0 | AW39: 0 | AX39: 0 | AZ39: 0 | BA39: 0 | BB39: 0 | BC39: 0 | BG39: 0 | BH39: 2 | BI39: 0 | BJ39: 0 | BL39: 0 | BM39: 0 | BP39: 0 | BQ39: 0 | BR39: 0 | BS39: 0 | BT39: 0 | BU39: 0 | BV39: 0 | BW39: 0 | BX39: 0 | BY39: 0 | BZ39: 0 | CA39: 0 | CB39: 0
A40: 45505 | AT40: 0 | AU40: 0 | AW40: 0 | AX40: 0 | AZ40: 0 | BA40: 0 | BB40: 0 | BC40: 0 | BG40: 0 | BH40: 4 | BI40: 0 | BJ40: 0 | BL40: 0 | BM40: 0 | BN40: 1 | BP40: 0 | BQ40: 0 | BR40: 0 | BS40: 0 | BT40: 0 | BU40: 0 | BV40: 0 | BW40: 0 | BX40: 0 | BY40: 0 | BZ40: 0 | CA40: 0 | CB40: 0
...

Sheet Large Sockeye
A1: Date | B1: MONTH | C1: DAY | D1: 1946 | E1: 1947 | F1: 1948 | G1: 1949 | H1: 1950 | I1: 1951 | J1: 1952 | K1: 1953 | L1: 1954 | M1: 1955 | N1: 1956 | O1: 1957 | P1: 1958 | Q1: 1959 | R1: 1960 | S1: 1961 | T1: 1962 | U1: 1963 | V1: 1964 | W1: 1965 | X1: 1966 | Y1: 1967 | Z1: 1968 | AA1: 1969 | AB1: 1970 | AC1: 1971 | AD1: 1972 | AE1: 1973 | AF1: 1974 | AG1: 1975 | AH1: 1976 | AI1: 1977 | AJ1: 1978 | AK1: 1979 | AL1: 1980 | AM1: 1981 | AN1: 1982 | AO1: 1983 | AP1: 1984 | AQ1: 1985 | AR1: 1986 | AS1: 1987 | AT1: 1988 | AU1: 1989 | AV1: 1990 | AW1: 1991 | AX1: 1992 | AY1: 1993 | AZ1: 1994 | BA1: 1995 | BB1: 1996 | BC1: 1997 | BD1: 1998 | BE1: 1999 | BF1: 2000 | BG1: 2001 | BH1: 2002 | BI1: 2003 | BJ1: 2004 | BK1: 2005 | BL1: 2006 | BM1: 2007 | BN1: 2008 | BO1: 2009 | BP1: 2010 | BQ1: 2011 | BR1: 2012 | BS1: 2013 | BT1: 2014 | BU1: 2015 | BV1: 2016 | BW1: 2017 | BX1: 2018 | BY1: 2019 | BZ1: 2020 | CA1: 2021 | CB1: 2022 | CC1: 2023 | CD1: 2024 | CE1: 2025
A2: 45467 | B2: 6 | C2: 24 | D2: 0 | E2: 0 | G2: 0 | H2: 0
A3: 45468 | B3: 6 | C3: 25 | D3: 0 | E3: 0 | G3: 0 | H3: 0 | BD3: 0
A4: 45469 | B4: 6 | C4: 26 | D4: 0 | E4: 0 | G4: 0 | H4: 0 | BD4: 0
A5: 45470 | B5: 6 | C5: 27 | D5: 0 | E5: 0 | G5: 0 | H5: 0 | BD5: 0
A6: 45471 | B6: 6 | C6: 28 | D6: 0 | E6: 0 | G6: 0 | H6: 0 | BD6: 0
A7: 45472 | B7: 6 | C7: 29 | D7: 0 | E7: 0 | G7: 0 | H7: 0 | BD7: 0
A8: 45473 | B8: 6 | C8: 30 | D8: 0 | E8: 1 | G8: 0 | H8: 0 | BD8: 0
A9: 45474 | B9: 7 | C9: 1 | D9: 0 | E9: 0 | G9: 0 | H9: 0 | AL9: 3 | AX9: 0.41424115 | BB9: 0.5920701 | BC9: 0.39125088 | BD9: 7 | BH9: 0.17796781
A10: 45475 | B10: 7 | C10: 2 | D10: 0 | E10: 0 | G10: 0 | H10: 0 | AL10: 4 | AX10: 1.0651915 | BA10: 3 | BB10: 1.522466 | BC10: 1.0060737 | BD10: 15 | BH10: 0.45763151
A11: 45476 | B11: 7 | C11: 3 | D11: 0 | E11: 0 | G11: 1 | H11: 0 | N11: 0 | AL11: 22 | AX11: 1.4202554 | BA11: 9 | BB11: 2.0299546 | BC11: 1.3414316 | BD11: 15 | BH11: 0.61017534
A12: 45477 | B12: 7 | C12: 4 | D12: 0 | E12: 0 | G12: 0 | H12: 0 | N12: 1 | AK12: 1 | AL12: 5 | AU12: 1 | AX12: 5.6810215 | BA12: 7 | BB12: 8.1198185 | BC12: 5.3657263 | BD12: 88 | BH12: 2.4407014
A13: 45478 | B13: 7 | C13: 5 | D13: 1 | E13: 2 | G13: 0 | H13: 0 | K13: 5 | M13: 0 | N13: 1 | AK13: 0 | AL13: 27 | AU13: 0 | AX13: 23.197505 | BA13: 15 | BB13: 33.155926 | BC13: 21.910049 | BD13: 377 | BH13: 9.9661972 | BJ13: 15
A14: 45479 | B14: 7 | C14: 6 | D14: 2 | E14: 5 | G14: 1 | H14: 0 | K14: 0 | M14: 1 | N14: 1 | O14: 1 | AK14: 0 | AL14: 6 | AU14: 0 | AX14: 35.447207 | BA14: 37 | BB14: 50.664284 | BC14: 33.479896 | BD14: 562 | BH14: 15.22896 | BJ14: 29 | BV14: 13
A15: 45480 | B15: 7 | C15: 7 | D15: 0 | E15: 0 | G15: 2 | H15: 0 | K15: 0 | M15: 0 | N15: 6 | O15: 0 | AG15: 1 | AK15: 0 | AL15: 16 | AQ15: 1 | AU15: 3 | AX15: 43.317789 | BA15: 36 | BB15: 61.913616 | BC15: 40.913663 | BD15: 692 | BH15: 18.610348 | BJ15: 45 | BL15: 4 | BV15: 20
A16: 45481 | B16: 7 | C16: 8 | D16: 1 | E16: 8 | G16: 1 | H16: 0 | K16: 17 | M16: 1 | N16: 6 | O16: 0 | P16: 40 | S16: 6 | AG16: 0 | AI16: 1 | AK16: 3 | AL16: 4 | AQ16: 3 | AU16: 10 | AW16: 0 | AX16: 63.08301 | AY16: 1 | BA16: 136 | BB16: 90.163818 | BC16: 59.581919 | BD16: 916 | BH16: 27.101955 | BJ16: 82 | BL16: 6 | BV16: 39
A17: 45482 | B17: 7 | C17: 9 | D17: 7 | E17: 10 | G17: 1 | H17: 0 | K17: 20 | M17: 0 | N17: 4 | O17: 0 | P17: 109 | S17: 2 | AG17: 0 | AI17: 3 | AK17: 3 | AL17: 21 | AP17: 2 | AQ17: 0 | AU17: 25 | AW17: 0 | AX17: 120.42582 | AY17: 2 | BA17: 268 | BB17: 172.12324 | BC17: 113.74222 | BD17: 1738 | BH17: 51.737784 | BJ17: 70 | BL17: 2 | BV17: 48 | CD17: 0
A18: 45483 | B18: 7 | C18: 10 | D18: 2 | E18: 4 | G18: 0 | H18: 3 | K18: 13 | M18: 0 | N18: 5 | O18: 2 | P18: 594 | S18: 7 | AB18: 0 | AG18: 1 | AI18: 2 | AK18: 1 | AL18: 160 | AO18: 1 | AP18: 1 | AQ18: 0 | AU18: 39 | AW18: 12 | AX18: 78.528287 | AY18: 6 | BA18: 366 | BB18: 112.23957 | BC18: 74.169988 | BD18: 902 | BH18: 33.737612 | BJ18: 68 | BL18: 3 | BV18: 83 | CD18: 0
A19: 45484 | B19: 7 | C19: 11 | D19: 28 | E19: 9 | G19: 1 | H19: 7 | K19: 30 | M19: 4 | N19: 11 | O19: 1 | P19: 1518 | S19: 3 | AB19: 0 | AE19: 1 | AF19: 1 | AG19: 8 | AI19: 10 | AJ19: 169 | AK19: 1 | AL19: 314 | AN19: 2 | AO19: 0 | AP19: 2 | AQ19: 0 | AU19: 90 | AW19: 6 | AX19: 92.671664 | AY19: 25 | BA19: 491 | BB19: 132.45454 | BC19: 87.52841 | BD19: 950 | BH19: 39.813941 | BJ19: 133 | BL19: 9 | BT19: 0 | BV19: 226 | CD19: 0
A20: 45485 | B20: 7 | C20: 12 | D20: 49 | E20: 15 | G20: 7 | H20: 14 | I20: 0 | K20: 76 | M20: 0 | N20: 22 | O20: 13 | P20: 5299 | R20: 1 | S20: 10 | T20: 0 | U20: 3 | AB20: 3 | AC20: 1 | AE20: 0 | AF20: 9 | AG20: 6 | AI20: 32 | AJ20: 633 | AK20: 7 | AL20: 627 | AM20: 6 | AN20: 4 | AO20: 1 | AP20: 1 | AQ20: 2 | AU20: 217 | AW20: 5 | AX20: 109.89226 | AY20: 41 | BA20: 907 | BB20: 157.06774 | BC20: 103.79327 | BD20: 679 | BH20: 47.212317 | BJ20: 338 | BK20: 3 | BL20: 11 | BP20: 2 | BT20: 0 | BV20: 898 | CD20: 0
A21: 45486 | B21: 7 | C21: 13 | D21: 191 | E21: 14 | G21: 18 | H21: 34 | I21: 0 | K21: 66 | M21: 0 | N21: 13 | O21: 4 | P21: 16625 | R21: 2 | S21: 14 | T21: 3 | U21: 1 | W21: 5 | AB21: 1 | AC21: 5 | AE21: 0 | AF21: 8 | AG21: 7 | AI21: 39 | AJ21: 825 | AK21: 9 | AL21: 1222 | AM21: 26 | AN21: 19 | AO21: 1 | AP21: 0 | AQ21: 3 | AU21: 273 | AW21: 24 | AX21: 153.38758 | AY21: 46 | BA21: 911 | BB21: 219.2351 | BC21: 144.87461 | BD21: 1315 | BH21: 65.898937 | BJ21: 720 | BK21: 0 | BL21: 19 | BP21: 1 | BT21: 11 | BV21: 1169 | BX21: 0 | CD21: 11
A22: 45487 | B22: 7 | C22: 14 | D22: 745 | E22: 35 | G22: 29 | H22: 119 | I22: 0 | K22: 52 | M22: 3 | N22: 13 | O22: 25 | P22: 28114 | R22: 0 | S22: 22 | T22: 1 | U22: 2 | W22: 6 | X22: 0 | AB22: 13 | AC22: 17 | AE22: 0 | AF22: 5 | AG22: 1 | AI22: 71 | AJ22: 1195 | AK22: 21 | AL22: 3325 | AM22: 17 | AN22: 287 | AO22: 3 | AP22: 0 | AQ22: 4 | AS22: 2 | AU22: 451 | AW22: 8 | AX22: 430.86998 | AY22: 138 | AZ22: 1 | BA22: 4879 | BB22: 615.83749 | BC22: 406.9568 | BD22: 1501 | BF22: 7 | BH22: 185.11194 | BJ22: 954 | BK22: 0 | BL22: 35 | BP22: 20 | BT22: 41 | BU22: 3145 | BV22: 1796 | BX22: 0 | CA22: 0 | CD22: 10
A23: 45488 | B23: 7 | C23: 15 | D23: 2410 | E23: 76 | G23: 29 | H23: 395 | I23: 0 | K23: 46 | M23: 1 | N23: 31 | O23: 8 | P23: 24849 | R23: 0 | S23: 22 | T23: 0 | U23: 5 | W23: 11 | X23: 11 | AA23: 4518 | AB23: 8 | AC23: 46 | AE23: 1 | AF23: 11 | AG23: 8 | AI23: 107 | AJ23: 1692 | AK23: 22 | AL23: 6586 | AM23: 44 | AN23: 336 | AO23: 5 | AP23: 0 | AQ23: 3 | AR23: 0 | AS23: 4 | AU23: 914 | AW23: 33 | AX23: 1322.0211 | AY23: 302 | AZ23: 3 | BA23: 19172 | BB23: 1889.5494 | BC23: 1248.6492 | BD23: 1555 | BF23: 13 | BH23: 567.97155 | BJ23: 1134 | BK23: 1 | BL23: 18 | BP23: 64 | BS23: 2 | BT23: 153 | BU23: 8392 | BV23: 2009 | BX23: 0 | CA23: 1 | CB23: 0 | CD23: 13 | CE23: 1
A24: 45489 | B24: 7 | C24: 16 | D24: 4150 | E24: 74 | G24: 29 | H24: 2158 | I24: 1 | K24: 132 | M24: 1 | N24: 37 | O24: 30 | P24: 9236 | R24: 1 | S24: 31 | T24: 0 | U24: 5 | W24: 20 | X24: 31 | Y24: 125 | AA24: 3520 | AB24: 14 | AC24: 34 | AE24: 7 | AF24: 9 | AG24: 12 | AI24: 184 | AJ24: 2433 | AK24: 51 | AL24: 9260 | AM24: 105 | AN24: 1162 | AO24: 14 | AP24: 0 | AQ24: 4 | AR24: 2 | AS24: 2 | AU24: 1246 | AW24: 70 | AX24: 1555.1205 | AY24: 7452 | AZ24: 5 | BA24: 13932 | BB24: 2222.7157 | BC24: 1468.8117 | BD24: 2387 | BF24: 3 | BH24: 668.11657 | BJ24: 1393 | BK24: 13 | BL24: 17 | BO24: 26 | BP24: 55 | BS24: 10 | BT24: 402 | BU24: 5858 | BV24: 3806 | BX24: 0 | BZ24: 0 | CA24: 1 | CB24: 2 | CD24: 128 | CE24: 6
A25: 45490 | B25: 7 | C25: 17 | D25: 751 | E25: 234 | G25: 15 | H25: 3251 | I25: 6 | K25: 251 | M25: 0 | N25: 151 | O25: 19 | P25: 11089 | R25: 1 | S25: 66 | T25: 1 | U25: 7 | W25: 12 | X25: 24 | Y25: 672 | AA25: 2139 | AB25: 70 | AC25: 65 | AE25: 7 | AF25: 9 | AG25: 9 | AI25: 238 | AJ25: 8735 | AK25: 63 | AL25: 6568 | AM25: 120 | AN25: 3598 | AO25: 17 | AP25: 3 | AQ25: 10 | AR25: 4 | AS25: 4 | AU25: 2396 | AW25: 59 | AX25: 1927.5233 | AY25: 8303 | AZ25: 10 | BA25: 15347 | BB25: 2754.9868 | BC25: 1820.5462 | BD25: 2783 | BF25: 38 | BH25: 828.10963 | BI25: 15 | BJ25: 4061 | BK25: 28 | BL25: 15 | BO25: 25 | BP25: 540 | BS25: 49 | BT25: 1696 | BU25: 3269 | BV25: 9440 | BW25: 15 | BX25: 23 | BZ25: 0 | CA25: 0 | CB25: 8 | CD25: 394 | CE25: 5
A26: 45491 | B26: 7 | C26: 18 | D26: 1142 | E26: 5739 | G26: 11 | H26: 5318 | I26: 51 | K26: 648 | M26: 4 | N26: 278 | O26: 20 | P26: 12214 | R26: 1 | S26: 105 | T26: 10 | U26: 2 | W26: 11 | X26: 14 | Y26: 3952 | AA26: 2610 | AB26: 76 | AC26: 69 | AE26: 8 | AF26: 13 | AG26: 8 | AI26: 473 | AJ26: 7458 | AK26: 92 | AL26: 4037 | AM26: 190 | AN26: 2910 | AO26: 39 | AP26: 5 | AQ26: 17 | AR26: 10 | AS26: 3 | AT26: 29 | AU26: 6192 | AW26: 42 | AX26: 1895.7451 | AY26: 7377 | AZ26: 9 | BA26: 13326 | BB26: 2709.5665 | BC26: 1790.5317 | BD26: 1944 | BF26: 132 | BH26: 814.45696 | BI26: 73 | BJ26: 12591 | BK26: 61 | BL26: 53 | BN26: 2 | BO26: 74 | BP26: 2780 | BS26: 125 | BT26: 21215 | BU26: 3300 | BV26: 15174 | BW26: 133 | BX26: 25 | BZ26: 3 | CA26: 0 | CB26: 10 | CD26: 383 | CE26: 17
A27: 45492 | B27: 7 | C27: 19 | D27: 2404 | E27: 8317 | G27: 9 | H27: 5803 | I27: 77 | K27: 8361 | M27: 8 | N27: 245 | O27: 128 | P27: 10902 | Q27: 1 | R27: 1 | S27: 327 | T27: 6 | U27: 0 | W27: 12 | X27: 43 | Y27: 6243 | AA27: 4643 | AB27: 100 | AC27: 189 | AE27: 27 | AF27: 26 | AG27: 8 | AI27: 420 | AJ27: 8774 | AK27: 101 | AL27: 4233 | AM27: 201 | AN27: 8427 | AO27: 65 | AP27: 11 | AQ27: 33 | AR27: 14 | AS27: 13 | AT27: 100 | AU27: 9330 | AW27: 259 | AX27: 2864.0633 | AY27: 11337 | AZ27: 25 | BA27: 15264 | BB27: 4093.5727 | BC27: 2705.1086 | BD27: 2534 | BF27: 986 | BH27: 1230.4694 | BI27: 94 | BJ27: 16029 | BK27: 231 | BL27: 87 | BN27: 1 | BO27: 15 | BP27: 8502 | BS27: 439 | BT27: 58948 | BU27: 4802 | BV27: 3990 | BW27: 1249 | BX27: 62 | BY27: 23 | BZ27: 2 | CA27: 54 | CB27: 10 | CD27: 791 | CE27: 35
A28: 45493 | B28: 7 | C28: 20 | D28: 1689 | E28: 3184 | G28: 13 | H28: 4292 | I28: 376 | K28: 4962 | M28: 13 | N28: 263 | O28: 349 | P28: 8108 | Q28: 0 | R28: 5 | S28: 1194 | T28: 38 | U28: 9 | W28: 21 | X28: 20 | Y28: 4180 | Z28: 30 | AA28: 6189 | AB28: 294 | AC28: 477 | AE28: 41 | AF28: 14 | AG28: 21 | AI28: 740 | AJ28: 8355 | AK28: 125 | AL28: 5009 | AM28: 246 | AN28: 18207 | AO28: 71 | AP28: 24 | AQ28: 36 | AR28: 32 | AS28: 6 | AT28: 1014 | AU28: 7444 | AW28: 690 | AX28: 3852.3836 | AY28: 11399 | AZ28: 30 | BA28: 17125 | BB28: 5506.1674 | BC28: 3638.5773 | BD28: 3637 | BE28: 0 | BF28: 5384 | BH28: 1655.0752 | BI28: 414 | BJ28: 6429 | BK28: 240 | BL28: 401 | BN28: 7 | BO28: 85 | BP28: 14767 | BS28: 404 | BT28: 26854 | BU28: 6711 | BV28: 4552 | BW28: 2621 | BX28: 111 | BY28: 43 | BZ28: 1 | CA28: 28 | CB28: 18 | CC28: 1567 | CD28: 2696 | CE28: 24
A29: 45494 | B29: 7 | C29: 21 | D29: 967 | E29: 1705 | G29: 20 | H29: 3227 | I29: 1150 | K29: 5413 | M29: 7 | N29: 303 | O29: 1786 | P29: 5969 | Q29: 0 | R29: 2 | S29: 1802 | T29: 32 | U29: 26 | W29: 8 | X29: 46 | Y29: 16517 | Z29: 345 | AA29: 8444 | AB29: 207 | AC29: 666 | AE29: 111 | AF29: 17 | AG29: 17 | AI29: 6671 | AJ29: 7160 | AK29: 245 | AL29: 6919 | AM29: 345 | AN29: 28499 | AO29: 258 | AP29: 22 | AQ29: 61 | AR29: 39 | AS29: 120 | AT29: 2085 | AU29: 9572 | AV29: 35 | AW29: 1153 | AX29: 4709.2118 | AY29: 12660 | AZ29: 76 | BA29: 19127 | BB29: 6730.8221 | BC29: 4447.8518 | BD29: 3238 | BE29: 7 | BF29: 2626 | BH29: 2023.1889 | BI29: 907 | BJ29: 5152 | BK29: 2973 | BL29: 3668 | BN29: 15 | BO29: 111 | BP29: 10029 | BS29: 442 | BT29: 23148 | BU29: 10722 | BV29: 2341 | BW29: 4555 | BX29: 7343 | BY29: 47 | BZ29: 9 | CA29: 46 | CB29: 25 | CC29: 12301 | CD29: 5925 | CE29: 176
A30: 45495 | B30: 7 | C30: 22 | D30: 1387 | E30: 963 | G30: 17 | H30: 1908 | I30: 1125 | J30: 0 | K30: 4597 | M30: 9 | N30: 453 | O30: 3057 | P30: 5786 | Q30: 0 | R30: 1 | S30: 8628 | T30: 88 | U30: 50 | W30: 34 | X30: 32 | Y30: 27869 | Z30: 1597 | AA30: 5170 | AB30: 521 | AC30: 1263 | AE30: 247 | AF30: 45 | AG30: 27 | AH30: 1 | AI30: 10581 | AJ30: 4815 | AK30: 242 | AL30: 8429 | AM30: 1082 | AN30: 24124 | AO30: 1269 | AP30: 41 | AQ30: 65 | AR30: 77 | AS30: 1215 | AT30: 2363 | AU30: 10400 | AV30: 177 | AW30: 12161 | AX30: 6030.5227 | AY30: 15591 | AZ30: 44 | BA30: 20893 | BB30: 8619.3565 | BC30: 5695.8303 | BD30: 5740 | BE30: 40 | BF30: 7666 | BG30: 40 | BH30: 2590.8553 | BI30: 3760 | BJ30: 4278 | BK30: 2726 | BL30: 32534 | BN30: 63 | BO30: 128 | BP30: 9368 | BS30: 763 | BT30: 23258 | BU30: 6546 | BV30: 1793 | BW30: 7301 | BX30: 22336 | BY30: 72 | BZ30: 8 | CA30: 228 | CB30: 45 | CC30: 14743 | CD30: 11449 | CE30: 438
A31: 45496 | B31: 7 | C31: 23 | D31: 1944 | E31: 991 | G31: 42 | H31: 5796 | I31: 1799 | J31: 0 | K31: 5394 | L31: 144 | M31: 17 | N31: 1249 | O31: 1580 | P31: 5112 | Q31: 2 | R31: 5 | S31: 30575 | T31: 62 | U31: 72 | W31: 22 | X31: 69 | Y31: 8942 | Z31: 6545 | AA31: 6592 | AB31: 351 | AC31: 1878 | AE31: 1534 | AF31: 56 | AG31: 366 | AH31: 0 | AI31: 16349 | AJ31: 4239 | AK31: 202 | AL31: 8051 | AM31: 2618 | AN31: 34432 | AO31: 5867 | AP31: 111 | AQ31: 117 | AR31: 64 | AS31: 6194 | AT31: 9085 | AU31: 11293 | AV31: 623 | AW31: 38820 | AX31: 10717.01 | AY31: 13780 | AZ31: 272 | BA31: 20946 | BB31: 15317.699 | BC31: 10122.219 | BD31: 5228 | BE31: 44 | BF31: 18556 | BG31: 15668 | BH31: 4604.2814 | BI31: 2670 | BJ31: 3860 | BK31: 4274 | BL31: 43535 | BN31: 688 | BO31: 2017 | BP31: 9079 | BR31: 8 | BS31: 855 | BT31: 19763 | BU31: 12251 | BV31: 2081 | BW31: 9539 | BX31: 12261 | BY31: 108 | BZ31: 7 | CA31: 914 | CB31: 47 | CC31: 9937 | CD31: 25407 | CE31: 915
A32: 45497 | B32: 7 | C32: 24 | D32: 1330 | E32: 603 | G32: 88 | H32: 4163 | I32: 2611 | J32: 0 | K32: 11743 | L32: 500 | M32: 26 | N32: 2469 | O32: 1401 | P32: 6976 | Q32: 6 | R32: 7 | S32: 11566 | T32: 213 | U32: 68 | W32: 37 | X32: 425 | Y32: 3758 | Z32: 13602 | AA32: 4417 | AB32: 3812 | AC32: 2714 | AE32: 3435 | AF32: 133 | AG32: 6486 | AH32: 0 | AI32: 8430 | AJ32: 4006 | AK32: 438 | AL32: 6623 | AM32: 6512 | AN32: 27106 | AO32: 7649 | AP32: 239 | AQ32: 586 | AR32: 82 | AS32: 10677 | AT32: 14783 | AU32: 14526 | AV32: 1356 | AW32: 39758 | AX32: 16243.579 | AY32: 22948 | AZ32: 441 | BA32: 23027 | BB32: 23216.76 | BC32: 15342.065 | BD32: 2875 | BE32: 123 | BF32: 47127 | BG32: 61187 | BH32: 6978.6262 | BI32: 3406 | BJ32: 2803 | BK32: 6869 | BL32: 45339 | BN32: 9805 | BO32: 1895 | BP32: 6667 | BR32: 84 | BS32: 7628 | BT32: 12174 | BU32: 9130 | BV32: 3132 | BW32: 7985 | BX32: 6750 | BY32: 198 | BZ32: 13 | CA32: 2167 | CB32: 51 | CC32: 7061 | CD32: 13068 | CE32: 5524
A33: 45498 | B33: 7 | C33: 25 | D33: 1517 | E33: 801 | G33: 123 | H33: 4376 | I33: 3510 | J33: 0 | K33: 8559 | L33: 3242 | M33: 104 | N33: 2769 | O33: 2862 | P33: 12913 | Q33: 8 | R33: 7 | S33: 8277 | T33: 34 | U33: 222 | W33: 54 | X33: 925 | Y33: 3847 | Z33: 20813 | AA33: 3416 | AB33: 3533 | AC33: 4158 | AE33: 3742 | AF33: 562 | AG33: 10049 | AH33: 0 | AI33: 4472 | AJ33: 5918 | AK33: 2506 | AL33: 6450 | AM33: 12472 | AN33: 23264 | AO33: 12611 | AP33: 1000 | AQ33: 5839 | AR33: 136 | AS33: 28073 | AT33: 24002 | AU33: 15006 | AV33: 956 | AW33: 19960 | AX33: 19841.441 | AY33: 27068 | AZ33: 1843 | BA33: 21872 | BB33: 28359.143 | BC33: 18740.246 | BD33: 2505 | BE33: 289 | BF33: 74793 | BG33: 76071 | BH33: 8524.3529 | BI33: 24203 | BJ33: 3707 | BK33: 8780 | BL33: 30386 | BN33: 22326 | BO33: 2797 | BP33: 6108 | BR33: 93 | BS33: 11792 | BT33: 16576 | BU33: 7504 | BV33: 2822 | BW33: 4487 | BX33: 12179 | BY33: 473 | BZ33: 18 | CA33: 2722 | CB33: 212 | CC33: 7448 | CD33: 15166 | CE33: 12331
A34: 45499 | B34: 7 | C34: 26 | D34: 2660 | E34: 1179 | G34: 1151 | H34: 4671 | I34: 3784 | J34: 0 | K34: 4404 | L34: 3502 | M34: 88 | N34: 3653 | O34: 13473 | P34: 15869 | Q34: 30 | R34: 8 | S34: 8048 | T34: 399 | U34: 723 | W34: 368 | X34: 1743 | Y34: 4703 | Z34: 25662 | AA34: 6357 | AB34: 6288 | AC34: 5691 | AE34: 6002 | AF34: 900 | AG34: 7643 | AH34: 0 | AI34: 3118 | AJ34: 6321 | AK34: 4609 | AL34: 7368 | AM34: 43734 | AN34: 7397 | AO34: 13794 | AP34: 2783 | AQ34: 5895 | AR34: 505 | AS34: 31981 | AT34: 28927 | AU34: 16966 | AV34: 1794 | AW34: 10221 | AX34: 14781.308 | AY34: 31699 | AZ34: 2092 | BA34: 15246 | BB34: 21126.753 | BC34: 13960.949 | BD34: 1130 | BE34: 1004 | BF34: 24889 | BG34: 53457 | BH34: 6350.3999 | BI34: 40875 | BJ34: 4003 | BK34: 12916 | BL34: 14163 | BN34: 59868 | BO34: 1737 | BP34: 8732 | BR34: 96 | BS34: 9512 | BT34: 18566 | BU34: 6578 | BV34: 2485 | BW34: 4692 | BX34: 11526 | BY34: 444 | BZ34: 13 | CA34: 4581 | CB34: 843 | CC34: 13797 | CD34: 18159 | CE34: 31816
A35: 45500 | B35: 7 | C35: 27 | D35: 3345 | E35: 1517 | G35: 2610 | H35: 5439 | I35: 3717 | J35: 1 | K35: 3819 | L35: 4449 | M35: 288 | N35: 10243 | O35: 14436 | P35: 13888 | Q35: 205 | R35: 7 | S35: 8279 | T35: 1211 | U35: 2270 | W35: 556 | X35: 1911 | Y35: 4668 | Z35: 18613 | AA35: 5660 | AB35: 797 | AC35: 16200 | AE35: 14790 | AF35: 3836 | AG35: 10825 | AH35: 0 | AI35: 2999 | AJ35: 4457 | AK35: 9333 | AL35: 6695 | AM35: 49755 | AN35: 6534 | AO35: 8261 | AP35: 8011 | AQ35: 7377 | AR35: 3352 | AS35: 27495 | AT35: 16673 | AU35: 22883 | AV35: 3878 | AW35: 8377 | AX35: 15151.166 | AY35: 37306 | AZ35: 6607 | BA35: 18246 | BB35: 21655.387 | BC35: 14310.28 | BD35: 2912 | BE35: 2903 | BF35: 18313 | BG35: 56902 | BH35: 6509.2997 | BI35: 48933 | BJ35: 6290 | BK35: 7742 | BL35: 13719 | BN35: 37700 | BO35: 1126 | BP35: 8575 | BR35: 577 | BS35: 7428 | BT35: 28226 | BU35: 6512 | BV35: 4574 | BW35: 6091 | BX35: 13454 | BY35: 367 | BZ35: 19 | CA35: 12554 | CB35: 5397 | CC35: 23332 | CD35: 16399 | CE35: 27517
A36: 45501 | B36: 7 | C36: 28 | D36: 2290 | E36: 1657 | G36: 3861 | H36: 4790 | I36: 2689 | J36: 4 | K36: 3626 | L36: 10744 | M36: 863 | N36: 3490 | O36: 7489 | P36: 12510 | Q36: 253 | R36: 31 | S36: 10003 | T36: 2644 | U36: 5162 | W36: 913 | X36: 1684 | Y36: 5131 | Z36: 9339 | AA36: 6858 | AB36: 6151 | AC36: 9684 | AE36: 32596 | AF36: 16677 | AG36: 12943 | AH36: 0 | AI36: 5782 | AJ36: 7547 | AK36: 14971 | AL36: 5564 | AM36: 54995 | AN36: 6554 | AO36: 10657 | AP36: 12538 | AQ36: 19362 | AR36: 4949 | AS36: 11251 | AT36: 28192 | AU36: 18270 | AV36: 15088 | AW36: 7380 | AX36: 15463.277 | AY36: 39206 | AZ36: 8287 | BA36: 17185 | BB36: 1141 | BC36: 14605.069 | BD36: 2400 | BE36: 3792 | BF36: 21480 | BG36: 48943 | BH36: 6643.39 | BI36: 17051 | BJ36: 9557 | BK36: 7728 | BL36: 13481 | BN36: 35252 | BO36: 15012 | BP36: 8166 | BR36: 1935 | BS36: 4686 | BT36: 28784 | BU36: 4652 | BV36: 4196 | BW36: 5819 | BX36: 15322 | BY36: 341 | BZ36: 34 | CA36: 11493 | CB36: 4229 | CC36: 23942 | CD36: 15879 | CE36: 32065
A37: 45502 | B37: 7 | C37: 29 | D37: 2764 | E37: 2445 | G37: 3496 | H37: 4725 | I37: 2328 | J37: 20 | K37: 4490 | L37: 15071 | M37: 880 | N37: 3703 | O37: 6728 | P37: 10720 | Q37: 7295 | R37: 42 | S37: 15075 | T37: 4054 | U37: 1962 | W37: 2665 | X37: 697 | Y37: 7711 | Z37: 5664 | AA37: 5276 | AB37: 6990 | AC37: 6982 | AE37: 58358 | AF37: 31658 | AG37: 14134 | AH37: 1 | AI37: 8244 | AJ37: 6462 | AK37: 32180 | AL37: 2955 | AM37: 52272 | AN37: 8306 | AO37: 13086 | AP37: 14749 | AQ37: 39705 | AR37: 7287 | AS37: 16670 | AT37: 18963 | AU37: 16966 | AV37: 20470 | AW37: 11305 | AX37: 9663 | AY37: 44716 | AZ37: 19897 | BA37: 16171 | BB37: 5428 | BC37: 5235 | BD37: 3075 | BE37: 4538 | BF37: 23895 | BG37: 56397 | BH37: 7704.5747 | BI37: 10932 | BJ37: 15157 | BK37: 14032 | BL37: 14891 | BN37: 43687 | BO37: 33440 | BP37: 8055 | BR37: 2474 | BS37: 5440 | BT37: 27926 | BU37: 5374 | BV37: 4804 | BW37: 7328 | BX37: 20858 | BY37: 449 | BZ37: 33 | CA37: 7839 | CB37: 28914 | CC37: 22516 | CD37: 14197 | CE37: 15784
A38: 45503 | B38: 7 | C38: 30 | D38: 5097 | E38: 4547 | G38: 4524 | H38: 3204 | I38: 2346 | J38: 39 | K38: 5262 | L38: 10025 | M38: 1114 | N38: 4856 | O38: 6643 | P38: 9810 | Q38: 19544 | R38: 113 | S38: 17332 | T38: 8011 | U38: 5224 | W38: 9073 | X38: 2530 | Y38: 9856 | Z38: 4764 | AA38: 7020 | AB38: 18550 | AC38: 8158 | AE38: 51889 | AF38: 56709 | AG38: 9006 | AH38: 1 | AI38: 7954 | AJ38: 9097 | AK38: 53106 | AL38: 2932 | AM38: 49342 | AN38: 14386 | AO38: 21431 | AP38: 15851 | AQ38: 67016 | AR38: 4868 | AS38: 17997 | AT38: 15490 | AU38: 14964 | AV38: 24471 | AW38: 10552 | AX38: 21401 | AY38: 30308 | AZ38: 29168 | BA38: 17745 | BB38: 26710 | BC38: 11382 | BD38: 5033 | BE38: 2092 | BF38: 23850 | BG38: 33428 | BH38: 8820.124 | BI38: 13402 | BJ38: 18584 | BK38: 10861 | BL38: 13539 | BN38: 26490 | BO38: 77923 | BP38: 8205 | BR38: 20871 | BS38: 7010 | BT38: 31775 | BU38: 6226 | BV38: 7345 | BW38: 6275 | BX38: 23637 | BY38: 1284 | BZ38: 33 | CA38: 7531 | CB38: 78670 | CC38: 20667 | CD38: 9611 | CE38: 25301
A39: 45504 | B39: 7 | C39: 31 | D39: 4220 | E39: 4776 | G39: 4375 | H39: 3641 | I39: 2292 | J39: 50 | K39: 3893 | L39: 3374 | M39: 2340 | N39: 5926 | O39: 6041 | P39: 8300 | Q39: 17546 | R39: 373 | S39: 14287 | T39: 8924 | U39: 6520 | W39: 17885 | X39: 7975 | Y39: 11064 | Z39: 5761 | AA39: 4926 | AB39: 22208 | AC39: 10336 | AE39: 45913 | AF39: 40525 | AG39: 5939 | AH39: 2 | AI39: 9392 | AJ39: 6207 | AK39: 66698 | AL39: 3154 | AM39: 41193 | AN39: 20579 | AO39: 20050 | AP39: 24937 | AQ39: 89368 | AR39: 9658 | AS39: 30986 | AT39: 26871 | AU39: 17770 | AV39: 21154 | AW39: 12492 | AX39: 26125 | AY39: 11349 | AZ39: 33083 | BA39: 19642 | BB39: 88638 | BC39: 5038 | BD39: 6541 | BE39: 3257 | BF39: 30386 | BG39: 29099 | BH39: 11389.166 | BI39: 17865 | BJ39: 15206 | BK39: 12236 | BL39: 18221 | BN39: 45017 | BO39: 27171 | BP39: 11951 | BR39: 48195 | BS39: 8560 | BT39: 27571 | BU39: 6644 | BV39: 9164 | BW39: 6144 | BX39: 18060 | BY39: 2033 | BZ39: 63 | CA39: 16022 | CB39: 95995 | CC39: 17592 | CD39: 10056 | CE39: 20898
A40: 45505 | B40: 8 | C40: 1 | D40: 6808 | E40: 5239 | G40: 2422 | H40: 3566 | I40: 2177 | J40: 65 | K40: 3322 | L40: 2275 | M40: 2734 | N40: 5980 | O40: 5254 | P40: 7829 | Q40: 8152 | R40: 957 | S40: 16323 | T40: 7528 | U40: 10034 | W40: 29213 | X40: 20822 | Y40: 13830 | Z40: 9030 | AA40: 8373 | AB40: 11059 | AC40: 10767 | AE40: 34293 | AF40: 26099 | AG40: 13970 | AH40: 3 | AI40: 12305 | AJ40: 6871 | AK40: 57826 | AL40: 6006 | AM40: 41330 | AN40: 26603 | AO40: 19118 | AP40: 37879 | AQ40: 97002 | AR40: 12886 | AS40: 31657 | AT40: 29017 | AU40: 12191 | AV40: 24209 | AW40: 16308 | AX40: 29630 | AY40: 14022 | AZ40: 28910 | BA40: 27566 | BB40: 163394 | BC40: 3751 | BD40: 8255 | BE40: 26841 | BF40: 31322 | BG40: 7497 | BH40: 14004.777 | BI40: 17413 | BJ40: 20244 | BK40: 13917 | BL40: 21883 | BN40: 30325 | BO40: 13078 | BP40: 13426 | BR40: 52663 | BS40: 8515 | BT40: 26853 | BU40: 7055 | BV40: 5811 | BW40: 15338 | BX40: 21004 | BY40: 2210 | BZ40: 114 | CA40: 14123 | CB40: 114013 | CC40: 20674 | CD40: 17509 | CE40: 21974
...

Sheet sk_cumu_prop_babine
A1: Date | B1: 1946 | C1: 1947 | D1: 1948 | E1: 1949 | F1: 1950 | G1: 1951 | H1: 1952 | I1: 1953 | J1: 1954 | K1: 1955 | L1: 1956 | M1: 1957 | N1: 1958 | O1: 1959 | P1: 1960 | Q1: 1961 | R1: 1962 | S1: 1963 | T1: 1964 | U1: 1965 | V1: 1966 | W1: 1967 | X1: 1968 | Y1: 1969 | Z1: 1970 | AA1: 1971 | AB1: 1972 | AC1: 1973 | AD1: 1974 | AE1: 1975 | AF1: 1976 | AG1: 1977 | AH1: 1978 | AI1: 1979 | AJ1: 1980 | AK1: 1981 | AL1: 1982 | AM1: 1983 | AN1: 1984 | AO1: 1985 | AP1: 1986 | AQ1: 1987 | AR1: 1988 | AS1: 1989 | AT1: 1990 | AU1: 1991 | AV1: 1992 | AW1: 1993 | AX1: 1994 | AY1: 1995 | AZ1: 1996 | BA1: 1997 | BB1: 1998 | BC1: 1999 | BD1: 2000 | BE1: 2001 | BF1: 2002 | BG1: 2003 | BH1: 2004 | BI1: 2005 | BJ1: 2006 | BK1: 2007 | BL1: 2008 | BM1: 2009 | BN1: 2010 | BO1: 2011 | BP1: 2012 | BQ1: 2013 | BR1: 2014 | BS1: 2015 | BT1: 2016 | BU1: 2017 | BV1: 2018 | BW1: 2019 | BX1: 2020 | BY1: 2021 | BZ1: 2022 | CA1: 2023 | CB1: 2024 | CC1: 2025
A2: 46197 | B2: =IF('Large Sockeye'!D2="","",SUM('Large Sockeye'!D$2:D2)/SUM('Large Sockeye'!D:D)) -> 0 | C2: =IF('Large Sockeye'!E2="","",SUM('Large Sockeye'!E$2:E2)/SUM('Large Sockeye'!E:E)) -> 0 | E2: =IF('Large Sockeye'!G2="","",SUM('Large Sockeye'!G$2:G2)/SUM('Large Sockeye'!G:G)) -> 0 | F2: =IF('Large Sockeye'!H2="","",SUM('Large Sockeye'!H$2:H2)/SUM('Large Sockeye'!H:H)) -> 0 | G2: 0 | H2: 0 | I2: 0 | J2: 0 | K2: 0 | L2: 0 | M2: 0 | N2: 0 | O2: 0 | P2: 0 | Q2: 0 | R2: 0 | S2: 0 | U2: 0 | V2: 0 | W2: 0 | X2: 0 | Y2: 0 | Z2: 0 | AA2: 0 | AB2: 0 | AC2: 0 | AD2: 0 | AE2: 0 | AF2: 0 | AG2: 0 | AH2: 0 | AI2: 0 | AJ2: 0 | AK2: 0 | AL2: 0 | AM2: 0 | AN2: 0 | AO2: 0 | AP2: 0 | AQ2: 0 | AR2: 0 | AS2: 0 | AT2: 0 | AU2: 0 | AV2: 0 | AW2: 0 | AX2: 0 | AY2: 0 | AZ2: 0 | BA2: 0 | BB2: 0 | BC2: 0 | BD2: 0 | BE2: 0 | BF2: 0 | BG2: 0 | BH2: 0 | BI2: 0 | BJ2: 0 | BK2: 0 | BL2: 0 | BM2: 0 | BN2: 0 | BO2: 0 | BP2: 0 | BQ2: 0 | BR2: 0 | BS2: 0 | BT2: 0 | BU2: 0 | BV2: 0 | BW2: 0 | BX2: 0 | BY2: 0 | BZ2: 0 | CA2: 0 | CB2: 0 | CC2: 0
A3: 46198 | B3: =IF('Large Sockeye'!D3="","",SUM('Large Sockeye'!D$2:D3)/SUM('Large Sockeye'!D:D)) -> 0 | C3: =IF('Large Sockeye'!E3="","",SUM('Large Sockeye'!E$2:E3)/SUM('Large Sockeye'!E:E)) -> 0 | E3: =IF('Large Sockeye'!G3="","",SUM('Large Sockeye'!G$2:G3)/SUM('Large Sockeye'!G:G)) -> 0 | F3: =IF('Large Sockeye'!H3="","",SUM('Large Sockeye'!H$2:H3)/SUM('Large Sockeye'!H:H)) -> 0 | G3: 0 | H3: 0 | I3: 0 | J3: 0 | K3: 0 | L3: 0 | M3: 0 | N3: 0 | O3: 0 | P3: 0 | Q3: 0 | R3: 0 | S3: 0 | U3: 0 | V3: 0 | W3: 0 | X3: 0 | Y3: 0 | Z3: 0 | AA3: 0 | AB3: 0 | AC3: 0 | AD3: 0 | AE3: 0 | AF3: 0 | AG3: 0 | AH3: 0 | AI3: 0 | AJ3: 0 | AK3: 0 | AL3: 0 | AM3: 0 | AN3: 0 | AO3: 0 | AP3: 0 | AQ3: 0 | AR3: 0 | AS3: 0 | AT3: 0 | AU3: 0 | AV3: 0 | AW3: 0 | AX3: 0 | AY3: 0 | AZ3: 0 | BA3: 0 | BB3: =IF('Large Sockeye'!BD3="","",SUM('Large Sockeye'!BD$2:BD3)/SUM('Large Sockeye'!BD:BD)) -> 0 | BC3: 0 | BD3: 0 | BE3: 0 | BF3: 0 | BG3: 0 | BH3: 0 | BI3: 0 | BJ3: 0 | BK3: 0 | BL3: 0 | BM3: 0 | BN3: 0 | BO3: 0 | BP3: 0 | BQ3: 0 | BR3: 0 | BS3: 0 | BT3: 0 | BU3: 0 | BV3: 0 | BW3: 0 | BX3: 0 | BY3: 0 | BZ3: 0 | CA3: 0 | CB3: 0 | CC3: 0
A4: 46199 | B4: =IF('Large Sockeye'!D4="","",SUM('Large Sockeye'!D$2:D4)/SUM('Large Sockeye'!D:D)) -> 0 | C4: =IF('Large Sockeye'!E4="","",SUM('Large Sockeye'!E$2:E4)/SUM('Large Sockeye'!E:E)) -> 0 | E4: =IF('Large Sockeye'!G4="","",SUM('Large Sockeye'!G$2:G4)/SUM('Large Sockeye'!G:G)) -> 0 | F4: =IF('Large Sockeye'!H4="","",SUM('Large Sockeye'!H$2:H4)/SUM('Large Sockeye'!H:H)) -> 0 | G4: 0 | H4: 0 | I4: 0 | J4: 0 | K4: 0 | L4: 0 | M4: 0 | N4: 0 | O4: 0 | P4: 0 | Q4: 0 | R4: 0 | S4: 0 | U4: 0 | V4: 0 | W4: 0 | X4: 0 | Y4: 0 | Z4: 0 | AA4: 0 | AB4: 0 | AC4: 0 | AD4: 0 | AE4: 0 | AF4: 0 | AG4: 0 | AH4: 0 | AI4: 0 | AJ4: 0 | AK4: 0 | AL4: 0 | AM4: 0 | AN4: 0 | AO4: 0 | AP4: 0 | AQ4: 0 | AR4: 0 | AS4: 0 | AT4: 0 | AU4: 0 | AV4: 0 | AW4: 0 | AX4: 0 | AY4: 0 | AZ4: 0 | BA4: 0 | BB4: =IF('Large Sockeye'!BD4="","",SUM('Large Sockeye'!BD$2:BD4)/SUM('Large Sockeye'!BD:BD)) -> 0 | BC4: 0 | BD4: 0 | BE4: 0 | BF4: 0 | BG4: 0 | BH4: 0 | BI4: 0 | BJ4: 0 | BK4: 0 | BL4: 0 | BM4: 0 | BN4: 0 | BO4: 0 | BP4: 0 | BQ4: 0 | BR4: 0 | BS4: 0 | BT4: 0 | BU4: 0 | BV4: 0 | BW4: 0 | BX4: 0 | BY4: 0 | BZ4: 0 | CA4: 0 | CB4: 0 | CC4: 0
A5: 46200 | B5: =IF('Large Sockeye'!D5="","",SUM('Large Sockeye'!D$2:D5)/SUM('Large Sockeye'!D:D)) -> 0 | C5: =IF('Large Sockeye'!E5="","",SUM('Large Sockeye'!E$2:E5)/SUM('Large Sockeye'!E:E)) -> 0 | E5: =IF('Large Sockeye'!G5="","",SUM('Large Sockeye'!G$2:G5)/SUM('Large Sockeye'!G:G)) -> 0 | F5: =IF('Large Sockeye'!H5="","",SUM('Large Sockeye'!H$2:H5)/SUM('Large Sockeye'!H:H)) -> 0 | G5: 0 | H5: 0 | I5: 0 | J5: 0 | K5: 0 | L5: 0 | M5: 0 | N5: 0 | O5: 0 | P5: 0 | Q5: 0 | R5: 0 | S5: 0 | U5: 0 | V5: 0 | W5: 0 | X5: 0 | Y5: 0 | Z5: 0 | AA5: 0 | AB5: 0 | AC5: 0 | AD5: 0 | AE5: 0 | AF5: 0 | AG5: 0 | AH5: 0 | AI5: 0 | AJ5: 0 | AK5: 0 | AL5: 0 | AM5: 0 | AN5: 0 | AO5: 0 | AP5: 0 | AQ5: 0 | AR5: 0 | AS5: 0 | AT5: 0 | AU5: 0 | AV5: 0 | AW5: 0 | AX5: 0 | AY5: 0 | AZ5: 0 | BA5: 0 | BB5: =IF('Large Sockeye'!BD5="","",SUM('Large Sockeye'!BD$2:BD5)/SUM('Large Sockeye'!BD:BD)) -> 0 | BC5: 0 | BD5: 0 | BE5: 0 | BF5: 0 | BG5: 0 | BH5: 0 | BI5: 0 | BJ5: 0 | BK5: 0 | BL5: 0 | BM5: 0 | BN5: 0 | BO5: 0 | BP5: 0 | BQ5: 0 | BR5: 0 | BS5: 0 | BT5: 0 | BU5: 0 | BV5: 0 | BW5: 0 | BX5: 0 | BY5: 0 | BZ5: 0 | CA5: 0 | CB5: 0 | CC5: 0
A6: 46201 | B6: =IF('Large Sockeye'!D6="","",SUM('Large Sockeye'!D$2:D6)/SUM('Large Sockeye'!D:D)) -> 0 | C6: =IF('Large Sockeye'!E6="","",SUM('Large Sockeye'!E$2:E6)/SUM('Large Sockeye'!E:E)) -> 0 | E6: =IF('Large Sockeye'!G6="","",SUM('Large Sockeye'!G$2:G6)/SUM('Large Sockeye'!G:G)) -> 0 | F6: =IF('Large Sockeye'!H6="","",SUM('Large Sockeye'!H$2:H6)/SUM('Large Sockeye'!H:H)) -> 0 | G6: 0 | H6: 0 | I6: 0 | J6: 0 | K6: 0 | L6: 0 | M6: 0 | N6: 0 | O6: 0 | P6: 0 | Q6: 0 | R6: 0 | S6: 0 | U6: 0 | V6: 0 | W6: 0 | X6: 0 | Y6: 0 | Z6: 0 | AA6: 0 | AB6: 0 | AC6: 0 | AD6: 0 | AE6: 0 | AF6: 0 | AG6: 0 | AH6: 0 | AI6: 0 | AJ6: 0 | AK6: 0 | AL6: 0 | AM6: 0 | AN6: 0 | AO6: 0 | AP6: 0 | AQ6: 0 | AR6: 0 | AS6: 0 | AT6: 0 | AU6: 0 | AV6: 0 | AW6: 0 | AX6: 0 | AY6: 0 | AZ6: 0 | BA6: 0 | BB6: =IF('Large Sockeye'!BD6="","",SUM('Large Sockeye'!BD$2:BD6)/SUM('Large Sockeye'!BD:BD)) -> 0 | BC6: 0 | BD6: 0 | BE6: 0 | BF6: 0 | BG6: 0 | BH6: 0 | BI6: 0 | BJ6: 0 | BK6: 0 | BL6: 0 | BM6: 0 | BN6: 0 | BO6: 0 | BP6: 0 | BQ6: 0 | BR6: 0 | BS6: 0 | BT6: 0 | BU6: 0 | BV6: 0 | BW6: 0 | BX6: 0 | BY6: 0 | BZ6: 0 | CA6: 0 | CB6: 0 | CC6: 0
A7: 46202 | B7: =IF('Large Sockeye'!D7="","",SUM('Large Sockeye'!D$2:D7)/SUM('Large Sockeye'!D:D)) -> 0 | C7: =IF('Large Sockeye'!E7="","",SUM('Large Sockeye'!E$2:E7)/SUM('Large Sockeye'!E:E)) -> 0 | E7: =IF('Large Sockeye'!G7="","",SUM('Large Sockeye'!G$2:G7)/SUM('Large Sockeye'!G:G)) -> 0 | F7: =IF('Large Sockeye'!H7="","",SUM('Large Sockeye'!H$2:H7)/SUM('Large Sockeye'!H:H)) -> 0 | G7: 0 | H7: 0 | I7: 0 | J7: 0 | K7: 0 | L7: 0 | M7: 0 | N7: 0 | O7: 0 | P7: 0 | Q7: 0 | R7: 0 | S7: 0 | U7: 0 | V7: 0 | W7: 0 | X7: 0 | Y7: 0 | Z7: 0 | AA7: 0 | AB7: 0 | AC7: 0 | AD7: 0 | AE7: 0 | AF7: 0 | AG7: 0 | AH7: 0 | AI7: 0 | AJ7: 0 | AK7: 0 | AL7: 0 | AM7: 0 | AN7: 0 | AO7: 0 | AP7: 0 | AQ7: 0 | AR7: 0 | AS7: 0 | AT7: 0 | AU7: 0 | AV7: 0 | AW7: 0 | AX7: 0 | AY7: 0 | AZ7: 0 | BA7: 0 | BB7: =IF('Large Sockeye'!BD7="","",SUM('Large Sockeye'!BD$2:BD7)/SUM('Large Sockeye'!BD:BD)) -> 0 | BC7: 0 | BD7: 0 | BE7: 0 | BF7: 0 | BG7: 0 | BH7: 0 | BI7: 0 | BJ7: 0 | BK7: 0 | BL7: 0 | BM7: 0 | BN7: 0 | BO7: 0 | BP7: 0 | BQ7: 0 | BR7: 0 | BS7: 0 | BT7: 0 | BU7: 0 | BV7: 0 | BW7: 0 | BX7: 0 | BY7: 0 | BZ7: 0 | CA7: 0 | CB7: 0 | CC7: 0
A8: 46203 | B8: =IF('Large Sockeye'!D8="","",SUM('Large Sockeye'!D$2:D8)/SUM('Large Sockeye'!D:D)) -> 0 | C8: =IF('Large Sockeye'!E8="","",SUM('Large Sockeye'!E$2:E8)/SUM('Large Sockeye'!E:E)) -> 3.7964063e-06 | E8: =IF('Large Sockeye'!G8="","",SUM('Large Sockeye'!G$2:G8)/SUM('Large Sockeye'!G:G)) -> 0 | F8: =IF('Large Sockeye'!H8="","",SUM('Large Sockeye'!H$2:H8)/SUM('Large Sockeye'!H:H)) -> 0 | G8: 0 | H8: 0 | I8: 0 | J8: 0 | K8: 0 | L8: 0 | M8: 0 | N8: 0 | O8: 0 | P8: 0 | Q8: 0 | R8: 0 | S8: 0 | U8: 0 | V8: 0 | W8: 0 | X8: 0 | Y8: 0 | Z8: 0 | AA8: 0 | AB8: 0 | AC8: 0 | AD8: 0 | AE8: 0 | AF8: 0 | AG8: 0 | AH8: 0 | AI8: 0 | AJ8: 0 | AK8: 0 | AL8: 0 | AM8: 0 | AN8: 0 | AO8: 0 | AP8: 0 | AQ8: 0 | AR8: 0 | AS8: 0 | AT8: 0 | AU8: 0 | AV8: 0 | AW8: 0 | AX8: 0 | AY8: 0 | AZ8: 0 | BA8: 0 | BB8: =IF('Large Sockeye'!BD8="","",SUM('Large Sockeye'!BD$2:BD8)/SUM('Large Sockeye'!BD:BD)) -> 0 | BC8: 0 | BD8: 0 | BE8: 0 | BF8: 0 | BG8: 0 | BH8: 0 | BI8: 0 | BJ8: 0 | BK8: 0 | BL8: 0 | BM8: 0 | BN8: 0 | BO8: 0 | BP8: 0 | BQ8: 0 | BR8: 0 | BS8: 0 | BT8: 0 | BU8: 0 | BV8: 0 | BW8: 0 | BX8: 0 | BY8: 0 | BZ8: 0 | CA8: 0 | CB8: 0 | CC8: 0
A9: 46204 | B9: =IF('Large Sockeye'!D9="","",SUM('Large Sockeye'!D$2:D9)/SUM('Large Sockeye'!D:D)) -> 0 | C9: =IF('Large Sockeye'!E9="","",SUM('Large Sockeye'!E$2:E9)/SUM('Large Sockeye'!E:E)) -> 3.7964063e-06 | E9: =IF('Large Sockeye'!G9="","",SUM('Large Sockeye'!G$2:G9)/SUM('Large Sockeye'!G:G)) -> 0 | F9: =IF('Large Sockeye'!H9="","",SUM('Large Sockeye'!H$2:H9)/SUM('Large Sockeye'!H:H)) -> 0 | G9: 0 | H9: 0 | I9: 0 | J9: 0 | K9: 0 | L9: 0 | M9: 0 | N9: 0 | O9: 0 | P9: 0 | Q9: 0 | R9: 0 | S9: 0 | U9: 0 | V9: 0 | W9: 0 | X9: 0 | Y9: 0 | Z9: 0 | AA9: 0 | AB9: 0 | AC9: 0 | AD9: 0 | AE9: 0 | AF9: 0 | AG9: 0 | AH9: 0 | AI9: 0 | AJ9: =IF('Large Sockeye'!AL9="","",SUM('Large Sockeye'!AL$2:AL9)/SUM('Large Sockeye'!AL:AL)) -> 5.6792475e-06 | AK9: 0 | AL9: 0 | AM9: 0 | AN9: 0 | AO9: 0 | AP9: 0 | AQ9: 0 | AR9: 0 | AS9: 0 | AT9: 0 | AU9: 0 | AV9: =IF('Large Sockeye'!AX9="","",SUM('Large Sockeye'!AX$2:AX9)/SUM('Large Sockeye'!AX:AX)) -> 3.2813214e-07 | AW9: 0 | AX9: 0 | AY9: 0 | AZ9: =IF('Large Sockeye'!BB9="","",SUM('Large Sockeye'!BB$2:BB9)/SUM('Large Sockeye'!BB:BB)) -> 2.890337e-07 | BA9: =IF('Large Sockeye'!BC9="","",SUM('Large Sockeye'!BC$2:BC9)/SUM('Large Sockeye'!BC:BC)) -> 3.5307124e-07 | BB9: =IF('Large Sockeye'!BD9="","",SUM('Large Sockeye'!BD$2:BD9)/SUM('Large Sockeye'!BD:BD)) -> 1.3665363e-05 | BC9: 0 | BD9: 0 | BE9: 0 | BF9: =IF('Large Sockeye'!BH9="","",SUM('Large Sockeye'!BH$2:BH9)/SUM('Large Sockeye'!BH:BH)) -> 2.9788089e-07 | BG9: 0 | BH9: 0 | BI9: 0 | BJ9: 0 | BK9: 0 | BL9: 0 | BM9: 0 | BN9: 0 | BO9: 0 | BP9: 0 | BQ9: 0 | BR9: 0 | BS9: 0 | BT9: 0 | BU9: 0 | BV9: 0 | BW9: 0 | BX9: 0 | BY9: 0 | BZ9: 0 | CA9: 0 | CB9: 0 | CC9: 0
A10: 46205 | B10: =IF('Large Sockeye'!D10="","",SUM('Large Sockeye'!D$2:D10)/SUM('Large Sockeye'!D:D)) -> 0 | C10: =IF('Large Sockeye'!E10="","",SUM('Large Sockeye'!E$2:E10)/SUM('Large Sockeye'!E:E)) -> 3.7964063e-06 | E10: =IF('Large Sockeye'!G10="","",SUM('Large Sockeye'!G$2:G10)/SUM('Large Sockeye'!G:G)) -> 0 | F10: =IF('Large Sockeye'!H10="","",SUM('Large Sockeye'!H$2:H10)/SUM('Large Sockeye'!H:H)) -> 0 | G10: 0 | H10: 0 | I10: 0 | J10: 0 | K10: 0 | L10: 0 | M10: 0 | N10: 0 | O10: 0 | P10: 0 | Q10: 0 | R10: 0 | S10: 0 | U10: 0 | V10: 0 | W10: 0 | X10: 0 | Y10: 0 | Z10: 0 | AA10: 0 | AB10: 0 | AC10: 0 | AD10: 0 | AE10: 0 | AF10: 0 | AG10: 0 | AH10: 0 | AI10: 0 | AJ10: =IF('Large Sockeye'!AL10="","",SUM('Large Sockeye'!AL$2:AL10)/SUM('Large Sockeye'!AL:AL)) -> 1.3251577e-05 | AK10: 0 | AL10: 0 | AM10: 0 | AN10: 0 | AO10: 0 | AP10: 0 | AQ10: 0 | AR10: 0 | AS10: 0 | AT10: 0 | AU10: 0 | AV10: =IF('Large Sockeye'!AX10="","",SUM('Large Sockeye'!AX$2:AX10)/SUM('Large Sockeye'!AX:AX)) -> 1.1719005e-06 | AW10: 0 | AX10: 0 | AY10: =IF('Large Sockeye'!BA10="","",SUM('Large Sockeye'!BA$2:BA10)/SUM('Large Sockeye'!BA:BA)) -> 1.7251254e-06 | AZ10: =IF('Large Sockeye'!BB10="","",SUM('Large Sockeye'!BB$2:BB10)/SUM('Large Sockeye'!BB:BB)) -> 1.0322632e-06 | BA10: =IF('Large Sockeye'!BC10="","",SUM('Large Sockeye'!BC$2:BC10)/SUM('Large Sockeye'!BC:BC)) -> 1.2609687e-06 | BB10: =IF('Large Sockeye'!BD10="","",SUM('Large Sockeye'!BD$2:BD10)/SUM('Large Sockeye'!BD:BD)) -> 4.2948282e-05 | BC10: 0 | BD10: 0 | BE10: 0 | BF10: =IF('Large Sockeye'!BH10="","",SUM('Large Sockeye'!BH$2:BH10)/SUM('Large Sockeye'!BH:BH)) -> 1.0638603e-06 | BG10: 0 | BH10: 0 | BI10: 0 | BJ10: 0 | BK10: 0 | BL10: 0 | BM10: 0 | BN10: 0 | BO10: 0 | BP10: 0 | BQ10: 0 | BR10: 0 | BS10: 0 | BT10: 0 | BU10: 0 | BV10: 0 | BW10: 0 | BX10: 0 | BY10: 0 | BZ10: 0 | CA10: 0 | CB10: 0 | CC10: 0
A11: 46206 | B11: =IF('Large Sockeye'!D11="","",SUM('Large Sockeye'!D$2:D11)/SUM('Large Sockeye'!D:D)) -> 0 | C11: =IF('Large Sockeye'!E11="","",SUM('Large Sockeye'!E$2:E11)/SUM('Large Sockeye'!E:E)) -> 3.7964063e-06 | E11: =IF('Large Sockeye'!G11="","",SUM('Large Sockeye'!G$2:G11)/SUM('Large Sockeye'!G:G)) -> 2.1594168e-06 | F11: =IF('Large Sockeye'!H11="","",SUM('Large Sockeye'!H$2:H11)/SUM('Large Sockeye'!H:H)) -> 0 | G11: 0 | H11: 0 | I11: 0 | J11: 0 | K11: 0 | L11: =IF('Large Sockeye'!N11="","",SUM('Large Sockeye'!N$2:N11)/SUM('Large Sockeye'!N:N)) -> 0 | M11: 0 | N11: 0 | O11: 0 | P11: 0 | Q11: 0 | R11: 0 | S11: 0 | U11: 0 | V11: 0 | W11: 0 | X11: 0 | Y11: 0 | Z11: 0 | AA11: 0 | AB11: 0 | AC11: 0 | AD11: 0 | AE11: 0 | AF11: 0 | AG11: 0 | AH11: 0 | AI11: 0 | AJ11: =IF('Large Sockeye'!AL11="","",SUM('Large Sockeye'!AL$2:AL11)/SUM('Large Sockeye'!AL:AL)) -> 5.4899392e-05 | AK11: 0 | AL11: 0 | AM11: 0 | AN11: 0 | AO11: 0 | AP11: 0 | AQ11: 0 | AR11: 0 | AS11: 0 | AT11: 0 | AU11: 0 | AV11: =IF('Large Sockeye'!AX11="","",SUM('Large Sockeye'!AX$2:AX11)/SUM('Large Sockeye'!AX:AX)) -> 2.296925e-06 | AW11: 0 | AX11: 0 | AY11: =IF('Large Sockeye'!BA11="","",SUM('Large Sockeye'!BA$2:BA11)/SUM('Large Sockeye'!BA:BA)) -> 6.9005017e-06 | AZ11: =IF('Large Sockeye'!BB11="","",SUM('Large Sockeye'!BB$2:BB11)/SUM('Large Sockeye'!BB:BB)) -> 2.0232359e-06 | BA11: =IF('Large Sockeye'!BC11="","",SUM('Large Sockeye'!BC$2:BC11)/SUM('Large Sockeye'!BC:BC)) -> 2.4714987e-06 | BB11: =IF('Large Sockeye'!BD11="","",SUM('Large Sockeye'!BD$2:BD11)/SUM('Large Sockeye'!BD:BD)) -> 7.2231202e-05 | BC11: 0 | BD11: 0 | BE11: 0 | BF11: =IF('Large Sockeye'!BH11="","",SUM('Large Sockeye'!BH$2:BH11)/SUM('Large Sockeye'!BH:BH)) -> 2.0851662e-06 | BG11: 0 | BH11: 0 | BI11: 0 | BJ11: 0 | BK11: 0 | BL11: 0 | BM11: 0 | BN11: 0 | BO11: 0 | BP11: 0 | BQ11: 0 | BR11: 0 | BS11: 0 | BT11: 0 | BU11: 0 | BV11: 0 | BW11: 0 | BX11: 0 | BY11: 0 | BZ11: 0 | CA11: 0 | CB11: 0 | CC11: 0
A12: 46207 | B12: =IF('Large Sockeye'!D12="","",SUM('Large Sockeye'!D$2:D12)/SUM('Large Sockeye'!D:D)) -> 0 | C12: =IF('Large Sockeye'!E12="","",SUM('Large Sockeye'!E$2:E12)/SUM('Large Sockeye'!E:E)) -> 3.7964063e-06 | E12: =IF('Large Sockeye'!G12="","",SUM('Large Sockeye'!G$2:G12)/SUM('Large Sockeye'!G:G)) -> 2.1594168e-06 | F12: =IF('Large Sockeye'!H12="","",SUM('Large Sockeye'!H$2:H12)/SUM('Large Sockeye'!H:H)) -> 0 | G12: 0 | H12: 0 | I12: 0 | J12: 0 | K12: 0 | L12: =IF('Large Sockeye'!N12="","",SUM('Large Sockeye'!N$2:N12)/SUM('Large Sockeye'!N:N)) -> 2.7987607e-06 | M12: 0 | N12: 0 | O12: 0 | P12: 0 | Q12: 0 | R12: 0 | S12: 0 | U12: 0 | V12: 0 | W12: 0 | X12: 0 | Y12: 0 | Z12: 0 | AA12: 0 | AB12: 0 | AC12: 0 | AD12: 0 | AE12: 0 | AF12: 0 | AG12: 0 | AH12: 0 | AI12: =IF('Large Sockeye'!AK12="","",SUM('Large Sockeye'!AK$2:AK12)/SUM('Large Sockeye'!AK:AK)) -> 8.5988589e-07 | AJ12: =IF('Large Sockeye'!AL12="","",SUM('Large Sockeye'!AL$2:AL12)/SUM('Large Sockeye'!AL:AL)) -> 6.4364805e-05 | AK12: 0 | AL12: 0 | AM12: 0 | AN12: 0 | AO12: 0 | AP12: 0 | AQ12: 0 | AR12: 0 | AS12: =IF('Large Sockeye'!AU12="","",SUM('Large Sockeye'!AU$2:AU12)/SUM('Large Sockeye'!AU:AU)) -> 8.815971e-07 | AT12: 0 | AU12: 0 | AV12: =IF('Large Sockeye'!AX12="","",SUM('Large Sockeye'!AX$2:AX12)/SUM('Large Sockeye'!AX:AX)) -> 6.7970228e-06 | AW12: 0 | AX12: 0 | AY12: =IF('Large Sockeye'!BA12="","",SUM('Large Sockeye'!BA$2:BA12)/SUM('Large Sockeye'!BA:BA)) -> 1.0925794e-05 | AZ12: =IF('Large Sockeye'!BB12="","",SUM('Large Sockeye'!BB$2:BB12)/SUM('Large Sockeye'!BB:BB)) -> 5.9871267e-06 | BA12: =IF('Large Sockeye'!BC12="","",SUM('Large Sockeye'!BC$2:BC12)/SUM('Large Sockeye'!BC:BC)) -> 7.3136185e-06 | BB12: =IF('Large Sockeye'!BD12="","",SUM('Large Sockeye'!BD$2:BD12)/SUM('Large Sockeye'!BD:BD)) -> 0.00024402433 | BC12: 0 | BD12: 0 | BE12: 0 | BF12: =IF('Large Sockeye'!BH12="","",SUM('Large Sockeye'!BH$2:BH12)/SUM('Large Sockeye'!BH:BH)) -> 6.1703898e-06 | BG12: 0 | BH12: 0 | BI12: 0 | BJ12: 0 | BK12: 0 | BL12: 0 | BM12: 0 | BN12: 0 | BO12: 0 | BP12: 0 | BQ12: 0 | BR12: 0 | BS12: 0 | BT12: 0 | BU12: 0 | BV12: 0 | BW12: 0 | BX12: 0 | BY12: 0 | BZ12: 0 | CA12: 0 | CB12: 0 | CC12: 0
A13: 46208 | B13: =IF('Large Sockeye'!D13="","",SUM('Large Sockeye'!D$2:D13)/SUM('Large Sockeye'!D:D)) -> 2.2396567e-06 | C13: =IF('Large Sockeye'!E13="","",SUM('Large Sockeye'!E$2:E13)/SUM('Large Sockeye'!E:E)) -> 1.1389219e-05 | E13: =IF('Large Sockeye'!G13="","",SUM('Large Sockeye'!G$2:G13)/SUM('Large Sockeye'!G:G)) -> 2.1594168e-06 | F13: =IF('Large Sockeye'!H13="","",SUM('Large Sockeye'!H$2:H13)/SUM('Large Sockeye'!H:H)) -> 0 | G13: 0 | H13: 0 | I13: =IF('Large Sockeye'!K13="","",SUM('Large Sockeye'!K$2:K13)/SUM('Large Sockeye'!K:K)) -> 7.2617528e-06 | J13: 0 | K13: =IF('Large Sockeye'!M13="","",SUM('Large Sockeye'!M$2:M13)/SUM('Large Sockeye'!M:M)) -> 0 | L13: =IF('Large Sockeye'!N13="","",SUM('Large Sockeye'!N$2:N13)/SUM('Large Sockeye'!N:N)) -> 5.5975214e-06 | M13: 0 | N13: 0 | O13: 0 | P13: 0 | Q13: 0 | R13: 0 | S13: 0 | U13: 0 | V13: 0 | W13: 0 | X13: 0 | Y13: 0 | Z13: 0 | AA13: 0 | AB13: 0 | AC13: 0 | AD13: 0 | AE13: 0 | AF13: 0 | AG13: 0 | AH13: 0 | AI13: =IF('Large Sockeye'!AK13="","",SUM('Large Sockeye'!AK$2:AK13)/SUM('Large Sockeye'!AK:AK)) -> 8.5988589e-07 | AJ13: =IF('Large Sockeye'!AL13="","",SUM('Large Sockeye'!AL$2:AL13)/SUM('Large Sockeye'!AL:AL)) -> 0.00011547803 | AK13: 0 | AL13: 0 | AM13: 0 | AN13: 0 | AO13: 0 | AP13: 0 | AQ13: 0 | AR13: 0 | AS13: =IF('Large Sockeye'!AU13="","",SUM('Large Sockeye'!AU$2:AU13)/SUM('Large Sockeye'!AU:AU)) -> 8.815971e-07 | AT13: 0 | AU13: 0 | AV13: =IF('Large Sockeye'!AX13="","",SUM('Large Sockeye'!AX$2:AX13)/SUM('Large Sockeye'!AX:AX)) -> 2.5172422e-05 | AW13: 0 | AX13: 0 | AY13: =IF('Large Sockeye'!BA13="","",SUM('Large Sockeye'!BA$2:BA13)/SUM('Large Sockeye'!BA:BA)) -> 1.9551421e-05 | AZ13: =IF('Large Sockeye'!BB13="","",SUM('Large Sockeye'!BB$2:BB13)/SUM('Large Sockeye'!BB:BB)) -> 2.2173014e-05 | BA13: =IF('Large Sockeye'!BC13="","",SUM('Large Sockeye'!BC$2:BC13)/SUM('Large Sockeye'!BC:BC)) -> 2.7085608e-05 | BB13: =IF('Large Sockeye'!BD13="","",SUM('Large Sockeye'!BD$2:BD13)/SUM('Large Sockeye'!BD:BD)) -> 0.00098000172 | BC13: 0 | BD13: 0 | BE13: 0 | BF13: =IF('Large Sockeye'!BH13="","",SUM('Large Sockeye'!BH$2:BH13)/SUM('Large Sockeye'!BH:BH)) -> 2.2851719e-05 | BG13: 0 | BH13: =IF('Large Sockeye'!BJ13="","",SUM('Large Sockeye'!BJ$2:BJ13)/SUM('Large Sockeye'!BJ:BJ)) -> 1.6282155e-05 | BI13: 0 | BJ13: 0 | BK13: 0 | BL13: 0 | BM13: 0 | BN13: 0 | BO13: 0 | BP13: 0 | BQ13: 0 | BR13: 0 | BS13: 0 | BT13: 0 | BU13: 0 | BV13: 0 | BW13: 0 | BX13: 0 | BY13: 0 | BZ13: 0 | CA13: 0 | CB13: 0 | CC13: 0
A14: 46209 | B14: =IF('Large Sockeye'!D14="","",SUM('Large Sockeye'!D$2:D14)/SUM('Large Sockeye'!D:D)) -> 6.7189701e-06 | C14: =IF('Large Sockeye'!E14="","",SUM('Large Sockeye'!E$2:E14)/SUM('Large Sockeye'!E:E)) -> 3.0371251e-05 | E14: =IF('Large Sockeye'!G14="","",SUM('Large Sockeye'!G$2:G14)/SUM('Large Sockeye'!G:G)) -> 4.3188336e-06 | F14: =IF('Large Sockeye'!H14="","",SUM('Large Sockeye'!H$2:H14)/SUM('Large Sockeye'!H:H)) -> 0 | G14: 0 | H14: 0 | I14: =IF('Large Sockeye'!K14="","",SUM('Large Sockeye'!K$2:K14)/SUM('Large Sockeye'!K:K)) -> 7.2617528e-06 | J14: 0 | K14: =IF('Large Sockeye'!M14="","",SUM('Large Sockeye'!M$2:M14)/SUM('Large Sockeye'!M:M)) -> 1.3641262e-05 | L14: =IF('Large Sockeye'!N14="","",SUM('Large Sockeye'!N$2:N14)/SUM('Large Sockeye'!N:N)) -> 8.3962821e-06 | M14: =IF('Large Sockeye'!O14="","",SUM('Large Sockeye'!O$2:O14)/SUM('Large Sockeye'!O:O)) -> 2.2982905e-06 | N14: 0 | O14: 0 | P14: 0 | Q14: 0 | R14: 0 | S14: 0 | U14: 0 | V14: 0 | W14: 0 | X14: 0 | Y14: 0 | Z14: 0 | AA14: 0 | AB14: 0 | AC14: 0 | AD14: 0 | AE14: 0 | AF14: 0 | AG14: 0 | AH14: 0 | AI14: =IF('Large Sockeye'!AK14="","",SUM('Large Sockeye'!AK$2:AK14)/SUM('Large Sockeye'!AK:AK)) -> 8.5988589e-07 | AJ14: =IF('Large Sockeye'!AL14="","",SUM('Large Sockeye'!AL$2:AL14)/SUM('Large Sockeye'!AL:AL)) -> 0.00012683653 | AK14: 0 | AL14: 0 | AM14: 0 | AN14: 0 | AO14: 0 | AP14: 0 | AQ14: 0 | AR14: 0 | AS14: =IF('Large Sockeye'!AU14="","",SUM('Large Sockeye'!AU$2:AU14)/SUM('Large Sockeye'!AU:AU)) -> 8.815971e-07 | AT14: 0 | AU14: 0 | AV14: =IF('Large Sockeye'!AX14="","",SUM('Large Sockeye'!AX$2:AX14)/SUM('Large Sockeye'!AX:AX)) -> 5.3251158e-05 | AW14: 0 | AX14: 0 | AY14: =IF('Large Sockeye'!BA14="","",SUM('Large Sockeye'!BA$2:BA14)/SUM('Large Sockeye'!BA:BA)) -> 4.0827968e-05 | AZ14: =IF('Large Sockeye'!BB14="","",SUM('Large Sockeye'!BB$2:BB14)/SUM('Large Sockeye'!BB:BB)) -> 4.6906041e-05 | BA14: =IF('Large Sockeye'!BC14="","",SUM('Large Sockeye'!BC$2:BC14)/SUM('Large Sockeye'!BC:BC)) -> 5.7298418e-05 | BB14: =IF('Large Sockeye'!BD14="","",SUM('Large Sockeye'!BD$2:BD14)/SUM('Large Sockeye'!BD:BD)) -> 0.0020771351 | BC14: 0 | BD14: 0 | BE14: 0 | BF14: =IF('Large Sockeye'!BH14="","",SUM('Large Sockeye'!BH$2:BH14)/SUM('Large Sockeye'!BH:BH)) -> 4.8341813e-05 | BG14: 0 | BH14: =IF('Large Sockeye'!BJ14="","",SUM('Large Sockeye'!BJ$2:BJ14)/SUM('Large Sockeye'!BJ:BJ)) -> 4.7760987e-05 | BI14: 0 | BJ14: 0 | BK14: 0 | BL14: 0 | BM14: 0 | BN14: 0 | BO14: 0 | BP14: 0 | BQ14: 0 | BR14: 0 | BS14: 0 | BT14: =IF('Large Sockeye'!BV14="","",SUM('Large Sockeye'!BV$2:BV14)/SUM('Large Sockeye'!BV:BV)) -> 1.4036649e-05 | BU14: 0 | BV14: 0 | BW14: 0 | BX14: 0 | BY14: 0 | BZ14: 0 | CA14: 0 | CB14: 0 | CC14: 0
A15: 46210 | B15: =IF('Large Sockeye'!D15="","",SUM('Large Sockeye'!D$2:D15)/SUM('Large Sockeye'!D:D)) -> 6.7189701e-06 | C15: =IF('Large Sockeye'!E15="","",SUM('Large Sockeye'!E$2:E15)/SUM('Large Sockeye'!E:E)) -> 3.0371251e-05 | E15: =IF('Large Sockeye'!G15="","",SUM('Large Sockeye'!G$2:G15)/SUM('Large Sockeye'!G:G)) -> 8.6376671e-06 | F15: =IF('Large Sockeye'!H15="","",SUM('Large Sockeye'!H$2:H15)/SUM('Large Sockeye'!H:H)) -> 0 | G15: 0 | H15: 0 | I15: =IF('Large Sockeye'!K15="","",SUM('Large Sockeye'!K$2:K15)/SUM('Large Sockeye'!K:K)) -> 7.2617528e-06 | J15: 0 | K15: =IF('Large Sockeye'!M15="","",SUM('Large Sockeye'!M$2:M15)/SUM('Large Sockeye'!M:M)) -> 1.3641262e-05 | L15: =IF('Large Sockeye'!N15="","",SUM('Large Sockeye'!N$2:N15)/SUM('Large Sockeye'!N:N)) -> 2.5188846e-05 | M15: =IF('Large Sockeye'!O15="","",SUM('Large Sockeye'!O$2:O15)/SUM('Large Sockeye'!O:O)) -> 2.2982905e-06 | N15: 0 | O15: 0 | P15: 0 | Q15: 0 | R15: 0 | S15: 0 | U15: 0 | V15: 0 | W15: 0 | X15: 0 | Y15: 0 | Z15: 0 | AA15: 0 | AB15: 0 | AC15: 0 | AD15: 0 | AE15: =IF('Large Sockeye'!AG15="","",SUM('Large Sockeye'!AG$2:AG15)/SUM('Large Sockeye'!AG:AG)) -> 1.2154065e-06 | AF15: 0 | AG15: 0 | AH15: 0 | AI15: =IF('Large Sockeye'!AK15="","",SUM('Large Sockeye'!AK$2:AK15)/SUM('Large Sockeye'!AK:AK)) -> 8.5988589e-07 | AJ15: =IF('Large Sockeye'!AL15="","",SUM('Large Sockeye'!AL$2:AL15)/SUM('Large Sockeye'!AL:AL)) -> 0.00015712585 | AK15: 0 | AL15: 0 | AM15: 0 | AN15: 0 | AO15: =IF('Large Sockeye'!AQ15="","",SUM('Large Sockeye'!AQ$2:AQ15)/SUM('Large Sockeye'!AQ:AQ)) -> 4.6511001e-07 | AP15: 0 | AQ15: 0 | AR15: 0 | AS15: =IF('Large Sockeye'!AU15="","",SUM('Large Sockeye'!AU$2:AU15)/SUM('Large Sockeye'!AU:AU)) -> 3.5263884e-06 | AT15: 0 | AU15: 0 | AV15: =IF('Large Sockeye'!AX15="","",SUM('Large Sockeye'!AX$2:AX15)/SUM('Large Sockeye'!AX:AX)) -> 8.7564404e-05 | AW15: 0 | AX15: 0 | AY15: =IF('Large Sockeye'!BA15="","",SUM('Large Sockeye'!BA$2:BA15)/SUM('Large Sockeye'!BA:BA)) -> 6.1529473e-05 | AZ15: =IF('Large Sockeye'!BB15="","",SUM('Large Sockeye'!BB$2:BB15)/SUM('Large Sockeye'!BB:BB)) -> 7.7130708e-05 | BA15: =IF('Large Sockeye'!BC15="","",SUM('Large Sockeye'!BC$2:BC15)/SUM('Large Sockeye'!BC:BC)) -> 9.4219582e-05 | BB15: =IF('Large Sockeye'!BD15="","",SUM('Large Sockeye'!BD$2:BD15)/SUM('Large Sockeye'!BD:BD)) -> 0.0034280538 | BC15: 0 | BD15: 0 | BE15: 0 | BF15: =IF('Large Sockeye'!BH15="","",SUM('Large Sockeye'!BH$2:BH15)/SUM('Large Sockeye'!BH:BH)) -> 7.9491642e-05 | BG15: 0 | BH15: =IF('Large Sockeye'!BJ15="","",SUM('Large Sockeye'!BJ$2:BJ15)/SUM('Large Sockeye'!BJ:BJ)) -> 9.660745e-05 | BI15: 0 | BJ15: =IF('Large Sockeye'!BL15="","",SUM('Large Sockeye'!BL$2:BL15)/SUM('Large Sockeye'!BL:BL)) -> 2.870089e-06 | BK15: 0 | BL15: 0 | BM15: 0 | BN15: 0 | BO15: 0 | BP15: 0 | BQ15: 0 | BR15: 0 | BS15: 0 | BT15: =IF('Large Sockeye'!BV15="","",SUM('Large Sockeye'!BV$2:BV15)/SUM('Large Sockeye'!BV:BV)) -> 3.5631493e-05 | BU15: 0 | BV15: 0 | BW15: 0 | BX15: 0 | BY15: 0 | BZ15: 0 | CA15: 0 | CB15: 0 | CC15: 0
A16: 46211 | B16: =IF('Large Sockeye'!D16="","",SUM('Large Sockeye'!D$2:D16)/SUM('Large Sockeye'!D:D)) -> 8.9586268e-06 | C16: =IF('Large Sockeye'!E16="","",SUM('Large Sockeye'!E$2:E16)/SUM('Large Sockeye'!E:E)) -> 6.0742501e-05 | E16: =IF('Large Sockeye'!G16="","",SUM('Large Sockeye'!G$2:G16)/SUM('Large Sockeye'!G:G)) -> 1.0797084e-05 | F16: =IF('Large Sockeye'!H16="","",SUM('Large Sockeye'!H$2:H16)/SUM('Large Sockeye'!H:H)) -> 0 | G16: 0 | H16: 0 | I16: =IF('Large Sockeye'!K16="","",SUM('Large Sockeye'!K$2:K16)/SUM('Large Sockeye'!K:K)) -> 3.1951712e-05 | J16: 0 | K16: =IF('Large Sockeye'!M16="","",SUM('Large Sockeye'!M$2:M16)/SUM('Large Sockeye'!M:M)) -> 2.7282524e-05 | L16: =IF('Large Sockeye'!N16="","",SUM('Large Sockeye'!N$2:N16)/SUM('Large Sockeye'!N:N)) -> 4.1981411e-05 | M16: =IF('Large Sockeye'!O16="","",SUM('Large Sockeye'!O$2:O16)/SUM('Large Sockeye'!O:O)) -> 2.2982905e-06 | N16: =IF('Large Sockeye'!P16="","",SUM('Large Sockeye'!P$2:P16)/SUM('Large Sockeye'!P:P)) -> 4.9139566e-05 | O16: 0 | P16: 0 | Q16: =IF('Large Sockeye'!S16="","",SUM('Large Sockeye'!S$2:S16)/SUM('Large Sockeye'!S:S)) -> 6.3581414e-06 | R16: 0 | S16: 0 | U16: 0 | V16: 0 | W16: 0 | X16: 0 | Y16: 0 | Z16: 0 | AA16: 0 | AB16: 0 | AC16: 0 | AD16: 0 | AE16: =IF('Large Sockeye'!AG16="","",SUM('Large Sockeye'!AG$2:AG16)/SUM('Large Sockeye'!AG:AG)) -> 1.2154065e-06 | AF16: 0 | AG16: =IF('Large Sockeye'!AI16="","",SUM('Large Sockeye'!AI$2:AI16)/SUM('Large Sockeye'!AI:AI)) -> 1.0638649e-06 | AH16: 0 | AI16: =IF('Large Sockeye'!AK16="","",SUM('Large Sockeye'!AK$2:AK16)/SUM('Large Sockeye'!AK:AK)) -> 3.4395436e-06 | AJ16: =IF('Large Sockeye'!AL16="","",SUM('Large Sockeye'!AL$2:AL16)/SUM('Large Sockeye'!AL:AL)) -> 0.00016469818 | AK16: 0 | AL16: 0 | AM16: 0 | AN16: 0 | AO16: =IF('Large Sockeye'!AQ16="","",SUM('Large Sockeye'!AQ$2:AQ16)/SUM('Large Sockeye'!AQ:AQ)) -> 1.86044e-06 | AP16: 0 | AQ16: 0 | AR16: 0 | AS16: =IF('Large Sockeye'!AU16="","",SUM('Large Sockeye'!AU$2:AU16)/SUM('Large Sockeye'!AU:AU)) -> 1.2342359e-05 | AT16: 0 | AU16: =IF('Large Sockeye'!AW16="","",SUM('Large Sockeye'!AW$2:AW16)/SUM('Large Sockeye'!AW:AW)) -> 0 | AV16: =IF('Large Sockeye'!AX16="","",SUM('Large Sockeye'!AX$2:AX16)/SUM('Large Sockeye'!AX:AX)) -> 0.00013753424 | AW16: =IF('Large Sockeye'!AY16="","",SUM('Large Sockeye'!AY$2:AY16)/SUM('Large Sockeye'!AY:AY)) -> 5.7490461e-07 | AX16: 0 | AY16: =IF('Large Sockeye'!BA16="","",SUM('Large Sockeye'!BA$2:BA16)/SUM('Large Sockeye'!BA:BA)) -> 0.00013973516 | AZ16: =IF('Large Sockeye'!BB16="","",SUM('Large Sockeye'!BB$2:BB16)/SUM('Large Sockeye'!BB:BB)) -> 0.00012114641 | BA16: =IF('Large Sockeye'!BC16="","",SUM('Large Sockeye'!BC$2:BC16)/SUM('Large Sockeye'!BC:BC)) -> 0.00014798729 | BB16: =IF('Large Sockeye'!BD16="","",SUM('Large Sockeye'!BD$2:BD16)/SUM('Large Sockeye'!BD:BD)) -> 0.0052162641 | BC16: 0 | BD16: 0 | BE16: 0 | BF16: =IF('Large Sockeye'!BH16="","",SUM('Large Sockeye'!BH$2:BH16)/SUM('Large Sockeye'!BH:BH)) -> 0.00012485465 | BG16: 0 | BH16: =IF('Large Sockeye'!BJ16="","",SUM('Large Sockeye'!BJ$2:BJ16)/SUM('Large Sockeye'!BJ:BJ)) -> 0.00018561656 | BI16: 0 | BJ16: =IF('Large Sockeye'!BL16="","",SUM('Large Sockeye'!BL$2:BL16)/SUM('Large Sockeye'!BL:BL)) -> 7.1752225e-06 | BK16: 0 | BL16: 0 | BM16: 0 | BN16: 0 | BO16: 0 | BP16: 0 | BQ16: 0 | BR16: 0 | BS16: 0 | BT16: =IF('Large Sockeye'!BV16="","",SUM('Large Sockeye'!BV$2:BV16)/SUM('Large Sockeye'!BV:BV)) -> 7.7741438e-05 | BU16: 0 | BV16: 0 | BW16: 0 | BX16: 0 | BY16: 0 | BZ16: 0 | CA16: 0 | CB16: 0 | CC16: 0
